examples/cpp_consumer_fetchcontent/tob_1000.csv
# Top of Book CSV Output
# Generated by TopOfBookTracker
# Symbol: 
# Date Range: 
# Columns:
#   timestamp: ISO 8601 timestamp (YYYY-MM-DDTHH:MM:SS.nnnnnnnnnZ)
#   symbol: Trading symbol
#   best_bid: Best bid price in dollars (converted from ticks)
#   best_ask: Best ask price in dollars (converted from ticks)
#   bid_volume: Volume at best bid level
#   ask_volume: Volume at best ask level
#   mid_price: Mid price in dollars ((bid + ask) / 2)
#   spread: Bid-ask spread in dollars (ask - bid)

timestamp,symbol,best_bid,best_ask,bid_volume,ask_volume,mid_price,spread
2024-06-28T15:30:00.000485984Z,ESU4,5558.00,0.00,1,0,0.00,0.00
2024-06-28T15:30:00.001120789Z,ESU4,5558.00,5558.75,1,1,5558.38,0.75
2024-06-28T15:30:00.001228823Z,ESU4,5558.00,5558.75,1,1,5558.38,0.75
2024-06-28T15:30:00.003035797Z,ESU4,5558.00,5558.75,1,3,5558.38,0.75
2024-06-28T15:30:00.003035797Z,ESU4,5558.00,5558.75,1,5,5558.38,0.75
2024-06-28T15:30:00.003035797Z,ESU4,5558.00,5558.75,1,6,5558.38,0.75
2024-06-28T15:30:00.003040456Z,ESU4,5558.00,5558.75,1,7,5558.38,0.75
2024-06-28T15:30:00.003044219Z,ESU4,5558.00,5558.75,1,8,5558.38,0.75
2024-06-28T15:30:00.003076254Z,ESU4,5558.00,5558.75,1,11,5558.38,0.75
2024-06-28T15:30:00.003098106Z,ESU4,5558.00,5558.75,1,15,5558.38,0.75
2024-06-28T15:30:00.003110009Z,ESU4,5558.00,5558.75,1,17,5558.38,0.75
2024-06-28T15:30:00.003120755Z,ESU4,5558.00,5558.75,1,18,5558.38,0.75
2024-06-28T15:30:00.003127872Z,ESU4,5558.00,5558.75,1,19,5558.38,0.75
2024-06-28T15:30:00.003153226Z,ESU4,5558.00,5558.75,1,21,5558.38,0.75
2024-06-28T15:30:00.003170347Z,ESU4,5558.00,5558.75,1,22,5558.38,0.75
2024-06-28T15:30:00.003176291Z,ESU4,5558.00,5558.75,1,23,5558.38,0.75
2024-06-28T15:30:00.003186428Z,ESU4,5558.50,5558.75,4,23,5558.62,0.25
2024-06-28T15:30:00.003195587Z,ESU4,5558.50,5558.75,6,23,5558.62,0.25
2024-06-28T15:30:00.003223311Z,ESU4,5558.50,5558.75,6,28,5558.62,0.25
2024-06-28T15:30:00.003243053Z,ESU4,5558.50,5558.75,8,28,5558.62,0.25
2024-06-28T15:30:00.003264705Z,ESU4,5558.50,5558.75,9,28,5558.62,0.25
2024-06-28T15:30:00.003272462Z,ESU4,5558.50,5558.75,9,29,5558.62,0.25
2024-06-28T15:30:00.003302761Z,ESU4,5558.50,5558.75,10,29,5558.62,0.25
2024-06-28T15:30:00.003309514Z,ESU4,5558.50,5558.75,10,29,5558.62,0.25
2024-06-28T15:30:00.003318499Z,ESU4,5558.50,5558.75,10,30,5558.62,0.25
2024-06-28T15:30:00.003335671Z,ESU4,5558.50,5558.75,11,30,5558.62,0.25
2024-06-28T15:30:00.003340540Z,ESU4,5558.50,5558.75,11,31,5558.62,0.25
2024-06-28T15:30:00.003357032Z,ESU4,5558.50,5558.75,16,31,5558.62,0.25
2024-06-28T15:30:00.003363170Z,ESU4,5558.50,5558.75,16,32,5558.62,0.25
2024-06-28T15:30:00.003368592Z,ESU4,5558.50,5558.69,16,1,5558.59,0.19
2024-06-28T15:30:00.003368592Z,ESU4,5558.50,5558.69,16,1,5558.59,0.19
2024-06-28T15:30:00.003407743Z,ESU4,5558.50,5558.69,16,1,5558.59,0.19
2024-06-28T15:30:00.003418777Z,ESU4,5558.50,5558.69,16,1,5558.59,0.19
2024-06-28T15:30:00.003433082Z,ESU4,5558.50,5558.69,17,1,5558.59,0.19
2024-06-28T15:30:00.004273183Z,ESU4,5558.50,5558.65,13,1,5558.57,0.15
2024-06-28T15:30:00.004273183Z,ESU4,5558.50,5558.65,13,1,5558.57,0.15
2024-06-28T15:30:00.004273183Z,ESU4,5558.50,5558.61,11,1,5558.56,0.11
2024-06-28T15:30:00.004273183Z,ESU4,5558.50,5558.61,11,1,5558.56,0.11
2024-06-28T15:30:00.004273183Z,ESU4,5557.75,5558.00,1,1,5557.88,0.25
2024-06-28T15:30:00.004273183Z,ESU4,5557.75,5558.00,1,1,5557.88,0.25
2024-06-28T15:30:00.004285563Z,ESU4,5557.75,5558.00,1,1,5557.88,0.25
2024-06-28T15:30:00.004285563Z,ESU4,5557.75,5558.00,1,1,5557.88,0.25
2024-06-28T15:30:00.004285563Z,ESU4,5557.75,5558.00,1,1,5557.88,0.25
2024-06-28T15:30:00.004290457Z,ESU4,5557.75,5558.00,1,1,5557.88,0.25
2024-06-28T15:30:00.004303163Z,ESU4,5557.75,5558.00,1,1,5557.88,0.25
2024-06-28T15:30:00.004306293Z,ESU4,5557.75,5558.00,1,1,5557.88,0.25
2024-06-28T15:30:00.004321094Z,ESU4,5557.75,5558.00,1,1,5557.88,0.25
2024-06-28T15:30:00.004338220Z,ESU4,5557.75,5558.00,1,1,5557.88,0.25
2024-06-28T15:30:00.004346489Z,ESU4,5557.75,5558.00,1,1,5557.88,0.25
2024-06-28T15:30:00.004375589Z,ESU4,5557.75,5558.00,1,1,5557.88,0.25
2024-06-28T15:30:00.004391856Z,ESU4,5557.75,5558.00,1,1,5557.88,0.25
2024-06-28T15:30:00.004418576Z,ESU4,5557.75,5558.00,1,1,5557.88,0.25
2024-06-28T15:30:00.004427454Z,ESU4,5557.75,5558.00,1,1,5557.88,0.25
2024-06-28T15:30:00.004434755Z,ESU4,5557.75,5558.00,1,1,5557.88,0.25
2024-06-28T15:30:00.004463923Z,ESU4,5557.75,5558.00,1,1,5557.88,0.25
2024-06-28T15:30:00.004493541Z,ESU4,5557.75,5558.00,1,1,5557.88,0.25
2024-06-28T15:30:00.004499117Z,ESU4,5557.75,5558.00,1,1,5557.88,0.25
2024-06-28T15:30:00.004516391Z,ESU4,5557.75,5558.00,1,1,5557.88,0.25
2024-06-28T15:30:00.004525202Z,ESU4,5557.75,5558.00,1,1,5557.88,0.25
2024-06-28T15:30:00.004531684Z,ESU4,5557.75,5558.00,1,1,5557.88,0.25
2024-06-28T15:30:00.004547857Z,ESU4,5557.75,5558.00,1,1,5557.88,0.25
2024-06-28T15:30:00.004572694Z,ESU4,5557.75,5558.00,1,1,5557.88,0.25
2024-06-28T15:30:00.004578346Z,ESU4,5557.75,5558.00,1,1,5557.88,0.25
2024-06-28T15:30:00.004589712Z,ESU4,5557.75,5558.00,1,1,5557.88,0.25
2024-06-28T15:30:00.004636492Z,ESU4,5558.25,5558.50,2,13,5558.38,0.25
2024-06-28T15:30:00.004644090Z,ESU4,5558.25,5558.50,5,13,5558.38,0.25
2024-06-28T15:30:00.004675992Z,ESU4,5558.25,5558.50,6,13,5558.38,0.25
2024-06-28T15:30:00.004686856Z,ESU4,5558.25,5558.50,7,13,5558.38,0.25
2024-06-28T15:30:00.004691295Z,ESU4,5558.25,5558.50,9,13,5558.38,0.25
2024-06-28T15:30:00.004697260Z,ESU4,5558.25,5558.50,9,13,5558.38,0.25
2024-06-28T15:30:00.004702948Z,ESU4,5558.25,5558.50,9,13,5558.38,0.25
2024-06-28T15:30:00.004708191Z,ESU4,5558.25,5558.50,9,13,5558.38,0.25
2024-06-28T15:30:00.004714539Z,ESU4,5558.25,5558.50,10,13,5558.38,0.25
2024-06-28T15:30:00.004721502Z,ESU4,5558.25,5558.50,15,13,5558.38,0.25
2024-06-28T15:30:00.004728506Z,ESU4,5558.25,5558.50,15,13,5558.38,0.25
2024-06-28T15:30:00.004733636Z,ESU4,5558.25,5558.50,15,13,5558.38,0.25
2024-06-28T15:30:00.004746845Z,ESU4,5558.25,5558.50,15,14,5558.38,0.25
2024-06-28T15:30:00.004751715Z,ESU4,5558.25,5558.50,15,14,5558.38,0.25
2024-06-28T15:30:00.004757474Z,ESU4,5558.25,5558.50,15,15,5558.38,0.25
2024-06-28T15:30:00.004764294Z,ESU4,5558.25,5558.50,15,16,5558.38,0.25
2024-06-28T15:30:00.004779449Z,ESU4,5558.25,5558.50,16,16,5558.38,0.25
2024-06-28T15:30:00.004791511Z,ESU4,5558.25,5558.50,17,16,5558.38,0.25
2024-06-28T15:30:00.004796969Z,ESU4,5558.25,5558.50,17,17,5558.38,0.25
2024-06-28T15:30:00.004804597Z,ESU4,5558.25,5558.50,17,17,5558.38,0.25
2024-06-28T15:30:00.004812717Z,ESU4,5558.25,5558.50,17,18,5558.38,0.25
2024-06-28T15:30:00.004817893Z,ESU4,5558.25,5558.50,17,20,5558.38,0.25
2024-06-28T15:30:00.004828451Z,ESU4,5558.25,5558.50,17,20,5558.38,0.25
2024-06-28T15:30:00.004833504Z,ESU4,5558.25,5558.50,17,25,5558.38,0.25
2024-06-28T15:30:00.004852207Z,ESU4,5558.25,5558.50,17,26,5558.38,0.25
2024-06-28T15:30:00.004883709Z,ESU4,5558.25,5558.50,19,26,5558.38,0.25
2024-06-28T15:30:00.004890314Z,ESU4,5558.25,5558.50,20,26,5558.38,0.25
2024-06-28T15:30:00.004895971Z,ESU4,5558.25,5558.50,21,26,5558.38,0.25
2024-06-28T15:30:00.004902331Z,ESU4,5558.25,5558.50,21,26,5558.38,0.25
2024-06-28T15:30:00.004907179Z,ESU4,5558.25,5558.50,21,26,5558.38,0.25
2024-06-28T15:30:00.004912099Z,ESU4,5558.25,5558.50,22,26,5558.38,0.25
2024-06-28T15:30:00.004965524Z,ESU4,5558.25,5558.50,22,26,5558.38,0.25
2024-06-28T15:30:00.004974192Z,ESU4,5558.25,5558.50,22,27,5558.38,0.25
2024-06-28T15:30:00.004988840Z,ESU4,5558.25,5558.50,22,28,5558.38,0.25
2024-06-28T15:30:00.005014316Z,ESU4,5558.25,5558.50,21,28,5558.38,0.25
2024-06-28T15:30:00.005209240Z,ESU4,5558.25,5558.50,21,27,5558.38,0.25
2024-06-28T15:30:00.005310541Z,ESU4,5558.25,5558.50,24,27,5558.38,0.25
2024-06-28T15:30:00.005427806Z,ESU4,5558.25,5558.50,24,27,5558.38,0.25
2024-06-28T15:30:00.005622053Z,ESU4,5558.25,5558.50,25,27,5558.38,0.25
2024-06-28T15:30:00.005711896Z,ESU4,5558.25,5558.50,25,26,5558.38,0.25
2024-06-28T15:30:00.005870739Z,ESU4,5558.25,5558.50,25,26,5558.38,0.25
2024-06-28T15:30:00.006588205Z,ESU4,5558.25,5558.50,25,25,5558.38,0.25
2024-06-28T15:30:00.006621719Z,ESU4,5558.25,5558.50,25,24,5558.38,0.25
