examples/cpp_consumer_fetchcontent/TOB_ES_DEMO_2025-07-07_2025-07-07.csv
# Top of Book CSV Output
# Generated by TopOfBookTracker
# Symbol: ES_DEMO
# Date Range: 2025-07-07_2025-07-07
# Columns:
#   timestamp: ISO 8601 timestamp (YYYY-MM-DDTHH:MM:SS.nnnnnnnnnZ)
#   symbol: Trading symbol
#   best_bid: Best bid price in dollars (converted from ticks)
#   best_ask: Best ask price in dollars (converted from ticks)
#   bid_volume: Volume at best bid level
#   ask_volume: Volume at best ask level
#   mid_price: Mid price in dollars ((bid + ask) / 2)
#   spread: Bid-ask spread in dollars (ask - bid)

timestamp,symbol,best_bid,best_ask,bid_volume,ask_volume,mid_price,spread
2025-07-07T21:41:31.034231160Z,DEMO,50.00,0.00,100,0,0.00,0.00
2025-07-07T21:41:31.034263956Z,DEMO,0.00,51.00,0,100,0.00,0.00
2025-07-07T21:41:31.034283145Z,DEMO,51.00,0.00,100,0,0.00,0.00
2025-07-07T21:41:31.034299048Z,DEMO,0.00,50.00,0,100,0.00,0.00
2025-07-07T21:41:31.034316483Z,DEMO,50.00,0.00,100,0,0.00,0.00
2025-07-07T21:41:31.034332794Z,DEMO,0.00,51.00,0,100,0.00,0.00
