examples/cpp_consumer_fetchcontent/TOB_ESU4_2025-07-10_2025-07-10.csv
# Top of Book CSV Output
# Generated by TopOfBookTracker
# Symbol: ESU4
# Date Range: 2025-07-10_2025-07-10
# Columns:
#   timestamp: ISO 8601 timestamp (YYYY-MM-DDTHH:MM:SS.nnnnnnnnnZ)
#   symbol: Trading symbol
#   best_bid: Best bid price in dollars (converted from ticks)
#   best_ask: Best ask price in dollars (converted from ticks)
#   bid_volume: Volume at best bid level
#   ask_volume: Volume at best ask level
#   mid_price: Mid price in dollars ((bid + ask) / 2)
#   spread: Bid-ask spread in dollars (ask - bid)

timestamp,symbol,best_bid,best_ask,bid_volume,ask_volume,mid_price,spread
2024-06-28T15:30:00.000500903Z,ESU4,5558.00,0.00,1,0,0.00,0.00
2024-06-28T15:30:00.001135098Z,ESU4,5558.00,5558.75,1,1,5558.38,0.75
2024-06-28T15:30:00.001242947Z,ESU4,5558.00,5558.75,1,1,5558.38,0.75
2024-06-28T15:30:00.003050032Z,ESU4,5558.00,5558.75,1,3,5558.38,0.75
2024-06-28T15:30:00.003050032Z,ESU4,5558.00,5558.75,1,5,5558.38,0.75
2024-06-28T15:30:00.003050032Z,ESU4,5558.00,5558.75,1,6,5558.38,0.75
2024-06-28T15:30:00.003053421Z,ESU4,5558.00,5558.75,1,7,5558.38,0.75
2024-06-28T15:30:00.003057125Z,ESU4,5558.00,5558.75,1,8,5558.38,0.75
2024-06-28T15:30:00.003088957Z,ESU4,5558.00,5558.75,1,11,5558.38,0.75
2024-06-28T15:30:00.003110475Z,ESU4,5558.00,5558.75,1,15,5558.38,0.75
2024-06-28T15:30:00.003121512Z,ESU4,5558.00,5558.75,1,17,5558.38,0.75
2024-06-28T15:30:00.003135642Z,ESU4,5558.00,5558.75,1,18,5558.38,0.75
2024-06-28T15:30:00.003140006Z,ESU4,5558.00,5558.75,1,19,5558.38,0.75
2024-06-28T15:30:00.003165874Z,ESU4,5558.00,5558.75,1,21,5558.38,0.75
2024-06-28T15:30:00.003182876Z,ESU4,5558.00,5558.75,1,22,5558.38,0.75
2024-06-28T15:30:00.003187826Z,ESU4,5558.00,5558.75,1,23,5558.38,0.75
2024-06-28T15:30:00.003199276Z,ESU4,5558.50,5558.75,4,23,5558.62,0.25
2024-06-28T15:30:00.003208164Z,ESU4,5558.50,5558.75,6,23,5558.62,0.25
2024-06-28T15:30:00.003234932Z,ESU4,5558.50,5558.75,6,28,5558.62,0.25
2024-06-28T15:30:00.003255348Z,ESU4,5558.50,5558.75,8,28,5558.62,0.25
2024-06-28T15:30:00.003277052Z,ESU4,5558.50,5558.75,9,28,5558.62,0.25
2024-06-28T15:30:00.003284924Z,ESU4,5558.50,5558.75,9,29,5558.62,0.25
2024-06-28T15:30:00.003316377Z,ESU4,5558.50,5558.75,10,29,5558.62,0.25
2024-06-28T15:30:00.003322224Z,ESU4,5558.50,5558.75,10,29,5558.62,0.25
2024-06-28T15:30:00.003333958Z,ESU4,5558.50,5558.75,10,30,5558.62,0.25
2024-06-28T15:30:00.003348098Z,ESU4,5558.50,5558.75,11,30,5558.62,0.25
2024-06-28T15:30:00.003352062Z,ESU4,5558.50,5558.75,11,31,5558.62,0.25
2024-06-28T15:30:00.003369264Z,ESU4,5558.50,5558.75,16,31,5558.62,0.25
2024-06-28T15:30:00.003376151Z,ESU4,5558.50,5558.75,16,32,5558.62,0.25
2024-06-28T15:30:00.003380652Z,ESU4,5558.50,5558.75,16,31,5558.62,0.25
2024-06-28T15:30:00.003420206Z,ESU4,5558.50,5558.75,16,32,5558.62,0.25
2024-06-28T15:30:00.003432973Z,ESU4,5558.50,5558.75,16,27,5558.62,0.25
2024-06-28T15:30:00.003445476Z,ESU4,5558.50,5558.75,17,27,5558.62,0.25
2024-06-28T15:30:00.004297333Z,ESU4,5558.50,5558.75,13,27,5558.62,0.25
2024-06-28T15:30:00.004297333Z,ESU4,5558.50,5558.75,11,27,5558.62,0.25
2024-06-28T15:30:00.004297333Z,ESU4,5558.50,5558.75,9,27,5558.62,0.25
2024-06-28T15:30:00.004297333Z,ESU4,5558.50,5558.75,8,27,5558.62,0.25
2024-06-28T15:30:00.004297333Z,ESU4,5558.50,5558.75,7,27,5558.62,0.25
2024-06-28T15:30:00.004297333Z,ESU4,5558.50,5558.75,6,27,5558.62,0.25
2024-06-28T15:30:00.004297333Z,ESU4,5558.50,5558.75,1,27,5558.62,0.25
2024-06-28T15:30:00.004297333Z,ESU4,5558.50,5558.75,0,27,5558.62,0.25
2024-06-28T15:30:00.004298151Z,ESU4,5558.50,5558.75,0,26,5558.62,0.25
2024-06-28T15:30:00.004298151Z,ESU4,5558.50,5558.75,0,25,5558.62,0.25
2024-06-28T15:30:00.004298151Z,ESU4,5558.50,5558.75,0,27,5558.62,0.25
2024-06-28T15:30:00.004302600Z,ESU4,5558.50,5558.75,0,28,5558.62,0.25
2024-06-28T15:30:00.004317276Z,ESU4,5558.50,5558.75,0,29,5558.62,0.25
2024-06-28T15:30:00.004317861Z,ESU4,5558.50,5558.75,0,31,5558.62,0.25
2024-06-28T15:30:00.004333798Z,ESU4,5558.50,5558.75,0,32,5558.62,0.25
2024-06-28T15:30:00.004359046Z,ESU4,5558.50,5558.75,0,44,5558.62,0.25
2024-06-28T15:30:00.004360952Z,ESU4,5558.50,5558.75,0,45,5558.62,0.25
2024-06-28T15:30:00.004389338Z,ESU4,5558.00,5558.50,1,1,5558.25,0.50
2024-06-28T15:30:00.004403123Z,ESU4,5558.00,5558.50,1,2,5558.25,0.50
2024-06-28T15:30:00.004431094Z,ESU4,5558.00,5558.50,1,3,5558.25,0.50
2024-06-28T15:30:00.004442843Z,ESU4,5558.00,5558.50,1,4,5558.25,0.50
2024-06-28T15:30:00.004446195Z,ESU4,5558.00,5558.50,1,4,5558.25,0.50
2024-06-28T15:30:00.004475400Z,ESU4,5558.00,5558.50,1,4,5558.25,0.50
2024-06-28T15:30:00.004504996Z,ESU4,5558.00,5558.50,1,4,5558.25,0.50
2024-06-28T15:30:00.004510731Z,ESU4,5558.00,5558.50,1,4,5558.25,0.50
2024-06-28T15:30:00.004528686Z,ESU4,5558.00,5558.50,1,5,5558.25,0.50
2024-06-28T15:30:00.004537387Z,ESU4,5558.00,5558.50,1,5,5558.25,0.50
2024-06-28T15:30:00.004544648Z,ESU4,5558.00,5558.50,1,6,5558.25,0.50
2024-06-28T15:30:00.004563831Z,ESU4,5558.00,5558.50,1,13,5558.25,0.50
2024-06-28T15:30:00.004585365Z,ESU4,5558.00,5558.50,1,13,5558.25,0.50
2024-06-28T15:30:00.004591115Z,ESU4,5558.00,5558.50,1,13,5558.25,0.50
2024-06-28T15:30:00.004601355Z,ESU4,5558.00,5558.50,1,13,5558.25,0.50
2024-06-28T15:30:00.004636053Z,ESU4,5558.25,5558.50,1,13,5558.38,0.25
2024-06-28T15:30:00.004649555Z,ESU4,5558.25,5558.50,3,13,5558.38,0.25
2024-06-28T15:30:00.004655690Z,ESU4,5558.25,5558.50,6,13,5558.38,0.25
2024-06-28T15:30:00.004690680Z,ESU4,5558.25,5558.50,7,13,5558.38,0.25
2024-06-28T15:30:00.004699824Z,ESU4,5558.25,5558.50,8,13,5558.38,0.25
2024-06-28T15:30:00.004703364Z,ESU4,5558.25,5558.50,10,13,5558.38,0.25
2024-06-28T15:30:00.004709824Z,ESU4,5558.25,5558.50,10,13,5558.38,0.25
2024-06-28T15:30:00.004715140Z,ESU4,5558.25,5558.50,10,13,5558.38,0.25
2024-06-28T15:30:00.004719815Z,ESU4,5558.25,5558.50,10,13,5558.38,0.25
2024-06-28T15:30:00.004727520Z,ESU4,5558.25,5558.50,11,13,5558.38,0.25
2024-06-28T15:30:00.004735625Z,ESU4,5558.25,5558.50,16,13,5558.38,0.25
2024-06-28T15:30:00.004741886Z,ESU4,5558.25,5558.50,16,13,5558.38,0.25
2024-06-28T15:30:00.004746399Z,ESU4,5558.25,5558.50,16,13,5558.38,0.25
2024-06-28T15:30:00.004759185Z,ESU4,5558.25,5558.50,16,14,5558.38,0.25
2024-06-28T15:30:00.004763312Z,ESU4,5558.25,5558.50,16,14,5558.38,0.25
2024-06-28T15:30:00.004769170Z,ESU4,5558.25,5558.50,16,15,5558.38,0.25
2024-06-28T15:30:00.004776878Z,ESU4,5558.25,5558.50,16,16,5558.38,0.25
2024-06-28T15:30:00.004793908Z,ESU4,5558.25,5558.50,17,16,5558.38,0.25
2024-06-28T15:30:00.004803836Z,ESU4,5558.25,5558.50,18,16,5558.38,0.25
2024-06-28T15:30:00.004808134Z,ESU4,5558.25,5558.50,18,17,5558.38,0.25
2024-06-28T15:30:00.004817151Z,ESU4,5558.25,5558.50,18,17,5558.38,0.25
2024-06-28T15:30:00.004825175Z,ESU4,5558.25,5558.50,18,18,5558.38,0.25
2024-06-28T15:30:00.004830131Z,ESU4,5558.25,5558.50,18,20,5558.38,0.25
2024-06-28T15:30:00.004841744Z,ESU4,5558.25,5558.50,18,20,5558.38,0.25
2024-06-28T15:30:00.004845286Z,ESU4,5558.25,5558.50,18,25,5558.38,0.25
2024-06-28T15:30:00.004865916Z,ESU4,5558.25,5558.50,18,26,5558.38,0.25
2024-06-28T15:30:00.004895059Z,ESU4,5558.25,5558.50,20,26,5558.38,0.25
2024-06-28T15:30:00.004902105Z,ESU4,5558.25,5558.50,21,26,5558.38,0.25
2024-06-28T15:30:00.004908342Z,ESU4,5558.25,5558.50,22,26,5558.38,0.25
2024-06-28T15:30:00.004915422Z,ESU4,5558.25,5558.50,22,26,5558.38,0.25
2024-06-28T15:30:00.004919647Z,ESU4,5558.25,5558.50,22,26,5558.38,0.25
2024-06-28T15:30:00.004923525Z,ESU4,5558.25,5558.50,23,26,5558.38,0.25
2024-06-28T15:30:00.004979918Z,ESU4,5558.25,5558.50,23,26,5558.38,0.25
2024-06-28T15:30:00.004986781Z,ESU4,5558.25,5558.50,23,27,5558.38,0.25
2024-06-28T15:30:00.005001264Z,ESU4,5558.25,5558.50,23,28,5558.38,0.25
2024-06-28T15:30:00.005026888Z,ESU4,5558.25,5558.50,22,28,5558.38,0.25
2024-06-28T15:30:00.005223244Z,ESU4,5558.25,5558.50,22,27,5558.38,0.25
2024-06-28T15:30:00.005325065Z,ESU4,5558.25,5558.50,25,27,5558.38,0.25
2024-06-28T15:30:00.005442591Z,ESU4,5558.25,5558.50,25,27,5558.38,0.25
2024-06-28T15:30:00.005636263Z,ESU4,5558.25,5558.50,26,27,5558.38,0.25
2024-06-28T15:30:00.005724433Z,ESU4,5558.25,5558.50,26,26,5558.38,0.25
